<?xml version="1.0"?>
<robot name="alice">

    <link name="base_link">
        <visual>
            <geometry>
                <cylinder length="0.01" radius=".053" />
            </geometry>
            <material name="black" />
            <origin rpy="0 0 0" xyz="0 0 0" />
        </visual>
        <inertial>
            <origin rpy="0 0 0" xyz="0 0 0" />
            <mass value="2" />
            <inertia ixx="0.015" ixy="0" ixz="0" iyy="0.00666666666667" iyz="0"
                izz="0.0216666666667" />
        </inertial>
    </link>


    <link name="link_1">
        <visual>
            <geometry>
                <mesh filename="package://alice_description/stl/braccio_base.stl"
                    scale="0.001 0.001 0.001" />
            </geometry>
            <material name="orange" />
            <origin rpy="0 0 3.1416" xyz="0 0.004 0" />
        </visual>

        <collision>
            <geometry>
                <mesh filename="package://alice_description/stl/braccio_base.stl"
                    scale="0.001 0.001 0.001" />
            </geometry>
            <origin rpy="0 0 3.1416" xyz="0 0.004 0" />
        </collision>

        <inertial>
            <origin rpy="0 0 3.1416" xyz="0 0.004 0" />
            <mass value="1" />
            <inertia ixx="0.015" ixy="0" ixz="0" iyy="0.00666666666667" iyz="0"
                izz="0.0216666666667" />
        </inertial>
    </link>

    <link name="link_2">
        <visual>
            <geometry>
                <mesh filename="package://alice_description/stl/braccio_shoulder.stl"
                    scale="0.001 0.001 0.001" />
            </geometry>
            <material name="orange" />
            <origin rpy="0 0 0" xyz="-0.0045 0.0055 -0.026" />
        </visual>
        <collision>
            <geometry>
                <mesh filename="package://alice_description/stl/braccio_shoulder.stl"
                    scale="0.001 0.001 0.001" />
            </geometry>
            <origin rpy="0 0 0" xyz="-0.0045 0.0055 -0.026" />
        </collision>
        <inertial>
            <origin rpy="0 0 0" xyz="-0.0045 0.0055 -0.026" />
            <mass value="0.1" />
            <inertia ixx="0.000348958333333" ixy="0" ixz="0" iyy="0.000348958333333" iyz="0"
                izz="3.125e-05" />
        </inertial>
    </link>

    <link name="link_3">
        <visual>
            <geometry>
                <mesh filename="package://alice_description/stl/braccio_elbow.stl"
                    scale="0.001 0.001 0.001" />
            </geometry>
            <material name="orange" />
            <origin rpy="0 0 0" xyz="-0.0045 0.005 -0.025" />
        </visual>
        <collision>
            <geometry>
                <mesh filename="package://alice_description/stl/braccio_elbow.stl"
                    scale="0.001 0.001 0.001" />
            </geometry>
            <origin rpy="0 0 0" xyz="-0.0045 0.005 -0.025" />
        </collision>
        <inertial>
            <origin rpy="0 0 0" xyz="-0.0045 0.005 -0.025" />
            <mass value="0.1" />
            <inertia ixx="0.000348958333333" ixy="0" ixz="0" iyy="0.000348958333333" iyz="0"
                izz="3.125e-05" />
        </inertial>
    </link>

    <link name="link_4">
        <visual>
            <geometry>
                <mesh filename="package://alice_description/stl/braccio_wrist_pitch.stl"
                    scale="0.001 0.001 0.001" />
            </geometry>
            <material name="orange" />
            <origin rpy="0 0 0" xyz="0.003 -0.0004 -0.024" />
        </visual>
        <collision>
            <geometry>
                <mesh filename="package://alice_description/stl/braccio_wrist_pitch.stl"
                    scale="0.001 0.001 0.001" />
            </geometry>
            <origin rpy="0 0 0" xyz="0.003 -0.0004 -0.024" />
        </collision>
        <inertial>
            <origin rpy="0 0 0" xyz="0.003 -0.0004 -0.024" />
            <mass value="0.1" />
            <inertia ixx="0.000348958333333" ixy="0" ixz="0" iyy="0.000348958333333" iyz="0"
                izz="3.125e-05" />
        </inertial>
    </link>

    <!-- <link name="link_5">
        <visual>
            <geometry>
                <mesh filename="package://alice_description/stl/braccio_wrist_roll.stl"
                    scale="0.001 0.001 0.001" />
            </geometry>
            <material name="white" />
            <origin rpy="0 0 0" xyz="0.006 0 0.0" />
        </visual>
        <collision>
            <geometry>
                <mesh filename="package://alice_description/stl/braccio_wrist_roll.stl"
                    scale="0.001 0.001 0.001" />
            </geometry>
            <origin rpy="0 0 0" xyz="0.006 0 0.0" />
        </collision>
        <inertial>
            <origin rpy="0 0 0" xyz="0.006 0 0.0" />
            <mass value="0.1" />
            <inertia ixx="0.000348958333333" ixy="0" ixz="0" iyy="0.000348958333333" iyz="0"
                izz="3.125e-05" />
        </inertial>
    </link> -->


    #Joints 
    <joint name="base_joint" type="revolute"> #Base joint is the rotating thing
        <axis xyz="0 0 -1" />
        <limit effort="1.0" lower="0.0" upper="3.1416" velocity="1.0" />
        <origin
            rpy="0 0 0" xyz="0 0 0" />
        <parent link="base_link" />
        <child link="link_1" />
        <dynamics
            damping="0.1" friction="0.001" />
    </joint>

    <joint name="shoulder_joint" type="revolute">
        <axis xyz="1 0 0" />
        <limit effort="1.0" lower="0.2618" upper="2.8798" velocity="1.0" />
        <origin rpy="-1.5708 0 0" xyz="0 -.002 0.072" />
        <parent link="link_1" />
        <child link="link_2" />
        <dynamics damping="0.1" friction="0.001" />
    </joint>

    <joint name="elbow_joint" type="revolute">
        <axis xyz="1 0 0" />
        <limit effort="1.0" lower="0" upper="3.1416" velocity="1.0" />
        <origin rpy="-1.5708 0 0" xyz="0 0 0.125" />
        <parent link="link_2" />
        <child link="link_3" />
        <dynamics damping="0.1" friction="0.001" />
    </joint>

    <joint name="wrist_pitch_joint" type="revolute">
        <axis xyz="1 0 0" />
        <limit effort="1.0" lower="0" upper="3.1416" velocity="1.0" />
        <origin rpy="-1.5708 0 0" xyz="0 0 0.125" />
        <parent link="link_3" />
        <child link="link_4" />
        <dynamics damping="0.1" friction="0.001" />
    </joint>


    #Gazebo 
    <gazebo reference="base_link">
        <mu1>1</mu1>
        <mu2>1</mu2>
        <selfCollide>true</selfCollide>
        <material>Gazebo/Turquoise</material>
    </gazebo>

    <gazebo reference="link_1">
        <mu1>1</mu1>
        <mu2>1</mu2>
        <selfCollide>true</selfCollide>
        <material>Gazebo/Green</material>
    </gazebo>

    <gazebo reference="link_2">
        <mu1>1</mu1>
        <mu2>1</mu2>
        <selfCollide>true</selfCollide>
        <material>Gazebo/Orange</material>
    </gazebo>

    <gazebo reference="link_3">
        <mu1>1</mu1>
        <mu2>1</mu2>
        <selfCollide>true</selfCollide>
        <material>Gazebo/Blue</material>
    </gazebo>

    <gazebo reference="link_4">
        <mu1>1</mu1>
        <mu2>1</mu2>
        <selfCollide>false</selfCollide>
        <material>Gazebo/Red</material>
    </gazebo>

    <!-- <gazebo reference="link_5">
        <mu1>1</mu1>
        <mu2>1</mu2>
        <selfCollide>true</selfCollide>
        <material>Gazebo/Purple</material>
    </gazebo> -->


    #Fixed base world 
    <link name="world"/>
    <joint name="world_joint" type="fixed">
        <parent link="world"/>
        <child link="base_link"/>
        <origin rpy="0.0 0.0 0.0" xyz="0.0 0.0 0.0"/>
    </joint>
</robot>