<?xml version="1.0" ?>
<!-- =================================================================================== -->
<!-- |    This document was autogenerated by xacro from /home/flimdejong/catkin_ws/src/alice_description/urdf/alice_v1.xacro | -->
<!-- |    EDITING THIS FILE BY HAND IS NOT RECOMMENDED                                 | -->
<!-- =================================================================================== -->
<robot name="alice">
    <!-- For gazebo ros control -->
    <gazebo>
        <plugin filename="libgazebo_ros_control.so" name="gazebo_ros_control">
            <robotNamespace>/alice</robotNamespace>
        </plugin>
    </gazebo>
    <gazebo reference="base_cyllinder">
        <turnGravityOff>true</turnGravityOff>
    </gazebo>
    <gazebo reference="rotating_base">
        <turnGravityOff>true</turnGravityOff>
    </gazebo>
    <gazebo reference="shoulder_link">
        <turnGravityOff>true</turnGravityOff>
    </gazebo>
    <gazebo reference="elbow_link">
        <turnGravityOff>true</turnGravityOff>
    </gazebo>
    <gazebo reference="wrist_link">
        <turnGravityOff>true</turnGravityOff>
    </gazebo>
    <!-- The base link is the cyllinder at the bottom-->
    <link name="base_cyllinder">
        <visual>
            <geometry>
                <cylinder length="0.003" radius=".053" />
            </geometry>
            <material name="black" />
            <origin rpy="0 0 0" xyz="0 0 0" />
        </visual>
        <inertial>
            <origin rpy="0 0 0" xyz="0 0 0" />
            <mass value="2" />
            <inertia ixx="0.015" ixy="0" ixz="0" iyy="0.00666666666667" iyz="0" izz="0.0216666666667" />
        </inertial>
        <collision>
            <geometry>
                <cylinder length="0.001" radius="0.053" />
            </geometry>
            <origin rpy="0 0 0" xyz="0 0 0" />
        </collision>
    </link>
    <!--Link 1 is the rotating base item-->
    <link name="rotating_base">
        <visual>
            <geometry>
                <mesh filename="package://alice_description/stl/braccio_base.stl" scale="0.001 0.001 0.001" />
            </geometry>
            <material name="orange" />
            <origin rpy="0 0 3.1416" xyz="0 0.004 0" />
        </visual>
        <collision>
            <geometry>
                <mesh filename="package://alice_description/stl/braccio_base.stl" scale="0.001 0.001 0.001" />
            </geometry>
            <origin rpy="0 0 3.1416" xyz="0 0.004 0" />
        </collision>
        <inertial>
            <origin rpy="0 0 3.1416" xyz="0 0.004 0" />
            <mass value="1" />
            <inertia ixx="0.015" ixy="0" ixz="0" iyy="0.00666666666667" iyz="0" izz="0.0216666666667" />
        </inertial>
    </link>
    <link name="shoulder_link">
        <visual>
            <geometry>
                <mesh filename="package://alice_description/stl/braccio_shoulder.stl" scale="0.001 0.001 0.001" />
            </geometry>
            <material name="orange" />
            <origin rpy="0 0 0" xyz="-0.0045 0.0055 -0.026" />
        </visual>
        <collision>
            <geometry>
                <mesh filename="package://alice_description/stl/braccio_shoulder.stl" scale="0.001 0.001 0.001" />
            </geometry>
            <origin rpy="0 0 0" xyz="-0.0045 0.0055 -0.026" />
        </collision>
        <inertial>
            <origin rpy="0 0 0" xyz="-0.0045 0.0055 -0.026" />
            <mass value="0.1" />
            <inertia ixx="0.000348958333333" ixy="0" ixz="0" iyy="0.000348958333333" iyz="0" izz="3.125e-05" />
        </inertial>
    </link>
    <link name="elbow_link">
        <visual>
            <geometry>
                <mesh filename="package://alice_description/stl/braccio_elbow.stl" scale="0.001 0.001 0.001" />
            </geometry>
            <material name="orange" />
            <origin rpy="0 0 0" xyz="-0.0045 0.005 -0.025" />
        </visual>
        <collision>
            <geometry>
                <mesh filename="package://alice_description/stl/braccio_elbow.stl" scale="0.001 0.001 0.001" />
            </geometry>
            <origin rpy="0 0 0" xyz="-0.0045 0.005 -0.025" />
        </collision>
        <inertial>
            <origin rpy="0 0 0" xyz="-0.0045 0.005 -0.025" />
            <mass value="0.1" />
            <inertia ixx="0.000348958333333" ixy="0" ixz="0" iyy="0.000348958333333" iyz="0" izz="3.125e-05" />
        </inertial>
    </link>
    <link name="wrist_link">
        <visual>
            <geometry>
                <mesh filename="package://alice_description/stl/braccio_wrist_pitch.stl" scale="0.001 0.001 0.001" />
            </geometry>
            <material name="orange" />
            <origin rpy="0 0 0" xyz="0.003 -0.0004 -0.024" />
        </visual>
        <collision>
            <geometry>
                <mesh filename="package://alice_description/stl/braccio_wrist_pitch.stl" scale="0.001 0.001 0.001" />
            </geometry>
            <origin rpy="0 0 0" xyz="0.003 -0.0004 -0.024" />
        </collision>
        <inertial>
            <origin rpy="0 0 0" xyz="0.003 -0.0004 -0.024" />
            <mass value="0.1" />
            <inertia ixx="0.000348958333333" ixy="0" ixz="0" iyy="0.000348958333333" iyz="0" izz="3.125e-05" />
        </inertial>
    </link>
    <!-- Base joint is the rotating thing -->
    <joint name="base_joint" type="revolute">
        <axis xyz="0 0 -1" />
        <limit effort="1.0" lower="0.0" upper="3.1416" velocity="1.0" />
        <origin rpy="0 0 0" xyz="0 0 0" />
        <parent link="base_cyllinder" />
        <child link="rotating_base" />
        <dynamics damping="0.1" friction="0.001" />
    </joint>
    <joint name="shoulder_joint" type="revolute">
        <axis xyz="1 0 0" />
        <limit effort="1.0" lower="0.2618" upper="2.8798" velocity="1.0" />
        <origin rpy="-1.5708 0 0" xyz="0 -.002 0.072" />
        <parent link="rotating_base" />
        <child link="shoulder_link" />
        <dynamics damping="0.1" friction="0.001" />
    </joint>
    <joint name="elbow_joint" type="revolute">
        <axis xyz="1 0 0" />
        <limit effort="1.0" lower="0" upper="3.1416" velocity="1.0" />
        <origin rpy="-1.5708 0 0" xyz="0 0 0.125" />
        <parent link="shoulder_link" />
        <child link="elbow_link" />
        <dynamics damping="0.1" friction="0.001" />
    </joint>
    <joint name="wrist_pitch_joint" type="revolute">
        <axis xyz="1 0 0" />
        <limit effort="1.0" lower="0" upper="3.1416" velocity="1.0" />
        <origin rpy="-1.5708 0 0" xyz="0 0 0.125" />
        <parent link="elbow_link" />
        <child link="wrist_link" />
        <dynamics damping="0.1" friction="0.001" />
    </joint>
    <gazebo reference="base_cyllinder">
        <mu1>1</mu1>
        <mu2>1</mu2>
        <selfCollide>true</selfCollide>
        <material>Gazebo/Turquoise</material>
    </gazebo>
    <gazebo reference="rotating_base">
        <mu1>1</mu1>
        <mu2>1</mu2>
        <selfCollide>true</selfCollide>
        <material>Gazebo/Green</material>
    </gazebo>
    <gazebo reference="shoulder_link">
        <mu1>1</mu1>
        <mu2>1</mu2>
        <selfCollide>true</selfCollide>
        <material>Gazebo/Orange</material>
    </gazebo>
    <gazebo reference="elbow_link">
        <mu1>1</mu1>
        <mu2>1</mu2>
        <selfCollide>true</selfCollide>
        <material>Gazebo/Blue</material>
    </gazebo>
    <gazebo reference="wrist_link">
        <mu1>1</mu1>
        <mu2>1</mu2>
        <selfCollide>false</selfCollide>
        <material>Gazebo/Red</material>
    </gazebo>
    <gazebo reference="realsense_camera">
        <selfCollide>false</selfCollide>
        <material>Gazebo/Black</material>
    </gazebo>
    <!-- Specify colors-->
    <material name="orange">
        <color rgba="0.57 0.17 0.0 1" />
    </material>
    <material name="white">
        <color rgba="0.8 0.8 0.8 1.0" />
    </material>
    <material name="black">
        <color rgba="0 0 0 0.50" />
    </material>
    <!-- Fixed world -->
    <link name="world" />
    <joint name="world_joint" type="fixed">
        <parent link="world" />
        <child link="base_cyllinder" />
        <origin rpy="0.0 0.0 0.0" xyz="0.0 0.0 0.0" />
    </joint>
    <!-- Including the camera urdf descriptions -->
    <!-- Cause it wouldnt load externally :/ -->
    <!-- Create the link (or like item) -->
    <link name="realsense_camera">
        <visual>
            <origin rpy="0 0 0" xyz="0 0 0" />
            <geometry>
                <box size="0.09 0.025 0.025" />
            </geometry>
            <material name="black" />
        </visual>
        <collision>
            <origin rpy="0 0 0" xyz="0 0 0" />
            <geometry>
                <box size="0.09 0.025 0.025" />
            </geometry>
        </collision>
        <inertial>
            <mass value="0.1" />
            <inertia ixx="0.000348958333333" ixy="0" ixz="0" iyy="0.000348958333333" iyz="0" izz="3.125e-05" />
            <origin xyz="0 0 0" rpy="0 0 0" />
        </inertial>
    </link>
    <joint name="camera_joint" type="fixed">
        <parent link="wrist_link" />
        <child link="realsense_camera" />
        <origin rpy="-1.5708 0 0" xyz="0 0 0.073" />
    </joint>
    <!-- Add alternative way to look at your camera -->
    <link name="realsense_camera_optical" />
    <joint name="camera_optical_joint" type="fixed">
        <parent link="realsense_camera" />
        <child link="realsense_camera_optical" />
        <origin rpy="-1.57079632679 0 -1.57079632679" xyz="0 0 0" />
    </joint>
    <!-- Gazebo reference for depth camera -->
    <gazebo reference="realsense_camera">
        <sensor name="camera_depth_sensor" type="depth">
            <always_on>true</always_on>
            <update_rate>20.0</update_rate>
            <camera>
                <horizontal_fov>1.047198</horizontal_fov>
                <image>
                    <width>640</width>
                    <height>480</height>
                    <format>R8G8B8</format>
                </image>
                <clip>
                    <near>0.05</near>
                    <far>3.0</far>
                </clip>
            </camera>
            <plugin filename="libgazebo_ros_openni_kinect.so" name="camera_plugin">
                <baseline>0.2</baseline>
                <alwaysOn>true</alwaysOn>
                <!-- Keep this zero, update_rate in the parent <sensor> tag will control the frame rate. -->
                <updateRate>0.0</updateRate>
                <cameraName>camera_ir</cameraName>
                <imageTopicName>/camera/color/image_raw</imageTopicName>
                <cameraInfoTopicName>/camera/color/camera_info</cameraInfoTopicName>
                <depthImageTopicName>/camera/depth/image_raw</depthImageTopicName>
                <depthImageCameraInfoTopicName>/camera/depth/camera_info</depthImageCameraInfoTopicName>
                <pointCloudTopicName>/camera/depth/points</pointCloudTopicName>
                <frameName>camera_link</frameName>
                <pointCloudCutoff>0.5</pointCloudCutoff>
                <pointCloudCutoffMax>3.0</pointCloudCutoffMax>
                <distortionK1>0</distortionK1>
                <distortionK2>0</distortionK2>
                <distortionK3>0</distortionK3>
                <distortionT1>0</distortionT1>
                <distortionT2>0</distortionT2>
                <CxPrime>0</CxPrime>
                <Cx>0</Cx>
                <Cy>0</Cy>
                <focalLength>0</focalLength>
                <hackBaseline>0</hackBaseline>
            </plugin>
        </sensor>
    </gazebo>
    <!-- Transmissions for MoveIt -->
    <transmission name="trans_base_joint">
        <type>transmission_interface/SimpleTransmission</type>
        <joint name="base_joint">
            <hardwareInterface>hardware_interface/EffortJointInterface</hardwareInterface>
        </joint>
        <actuator name="base_joint_motor">
            <hardwareInterface>hardware_interface/EffortJointInterface</hardwareInterface>
            <mechanicalReduction>1</mechanicalReduction>
        </actuator>
    </transmission>
    <transmission name="trans_shoulder_joint">
        <type>transmission_interface/SimpleTransmission</type>
        <joint name="shoulder_joint">
            <hardwareInterface>hardware_interface/EffortJointInterface</hardwareInterface>
        </joint>
        <actuator name="shoulder_joint_motor">
            <hardwareInterface>hardware_interface/EffortJointInterface</hardwareInterface>
            <mechanicalReduction>1</mechanicalReduction>
        </actuator>
    </transmission>
    <transmission name="trans_elbow_joint">
        <type>transmission_interface/SimpleTransmission</type>
        <joint name="elbow_joint">
            <hardwareInterface>hardware_interface/EffortJointInterface</hardwareInterface>
        </joint>
        <actuator name="elbow_joint_motor">
            <hardwareInterface>hardware_interface/EffortJointInterface</hardwareInterface>
            <mechanicalReduction>1</mechanicalReduction>
        </actuator>
    </transmission>
    <transmission name="trans_wrist_pitch_joint">
        <type>transmission_interface/SimpleTransmission</type>
        <joint name="wrist_pitch_joint">
            <hardwareInterface>hardware_interface/EffortJointInterface</hardwareInterface>
        </joint>
        <actuator name="wrist_pitch_joint_motor">
            <hardwareInterface>hardware_interface/EffortJointInterface</hardwareInterface>
            <mechanicalReduction>1</mechanicalReduction>
        </actuator>
    </transmission>
</robot>

